Workbook

Sheet PNT-G-133
B1: صورت مجلس | E1: شماره ویرایش مدرک: | H1: تاریخ ویرایش مدرک: | K1: EC-01-F-09
F4: صورتمجلس
B11: نام پروژه: تعمیرات اساسی ضلع جنوبی اسکله شرقی جزیره خارگ ازمحور19الی45 (PC) | F11: شماره صورتمجلس PNT-G-133 | J11: تاریخ :1404/07/28
B14: نام پیمانکار: شرکت صنایع فرا ساحل (صف) | F14: شماره قرارداد: 11048-73-38 | J14: تعداد صفحات پيوست: 5 صفحه
B17: موضـوع: تهیه رنگ High Solid GLASS FLAKE EPOXY به ضخامت 250 میکرون
B20: بدینوسیله امضا کنندگان ذیل تایید می نمایند , تهیه رنگ High Solid GLASS FLAKE EPOXY به ضخامت 250 میکرون برای المان های ناحیه حد فاصل محور های 19 الی 45 ضلع جنوبی اسکله شرقی مطابق با ریزمتره پیوست به مساحت 361/4 متر مربع انجام گردید.
B26: ردیف | C26: ردیف فهرست بها | E26: شرح | I26: مقدار | K26: واحد
B28: 28 | C28: 641904105 | E28: تهیه رنگ High Solid GLASS FLAKE EPOXY به ضخامت 250 میکرون | I28: 361/4 | K28: متر مربع
B31: پیمانکار | F31: دستگاه نظارت | J31: کار فرما
B35: منبع مدرک: کارفرما ناظر مقیم پروژه امور قرارداد ها بایگانی دستگاه نظارت پیمانکار

Sheet PNT-G-132
B1: صورت مجلس | E1: شماره ویرایش مدرک: | H1: تاریخ ویرایش مدرک: | K1: EC-01-F-09
F4: صورتمجلس
B11: نام پروژه: تعمیرات اساسی ضلع جنوبی اسکله شرقی جزیره خارگ ازمحور19الی45 (PC) | F11: شماره صورت PNT-G-132 | J11: تاریخ :1404/07/28
B14: نام پیمانکار: شرکت صنایع فرا ساحل (صف) | F14: شماره قرارداد: 11048-73-38 | J14: تعداد صفحات پيوست: 4 صفحه
B17: موضـوع: اضافه بها اعمال رنگ High Solid GLASS FLAKE EPOXY به وسیله دستگاه رنگ پاش بدون هوا (Airless) به ضخامت 250 میکرون درناحیه بالای اسپلش زون تا زیر عرشه اسکله معادل 20% بهای واحد ردیف 641903107 طبق بند 13 مقدمه فصل 19 فهرست بها
B20: بدینوسیله امضا کنندگان ذیل تایید می نمایند , عملیات اعمال رنگ High Solid GLASS FLAKE EPOXY به وسیله دستگاه رنگ پاش بدون هوا (Airless) به ضخامت 250 میکرون در درناحیه بالای اسپلش زون تا زیر عرشه اسکله بر روی المان های ناحیه حد فاصل محور های 19 الی 45 ضلع جنوبی اسکله شرقی مطابق با ریزمتره پیوست به مساحت 361/4 متر مربع انجام گردید.
B26: ردیف | C26: ردیف فهرست بها | E26: شرح | I26: مقدار | K26: واحد
B28: 24 | C28: 641903132* | E28: اضافه بها اعمال رنگ High Solid GLASS FLAKE EPOXY به وسیله دستگاه رنگ پاش بدون هوا (Airless) به ضخامت 250 میکرون درناحیه بالای اسپلش زون تا زیر عرشه اسکله معادل 20% بهای واحد ردیف 641903107 طبق بند 13 مقدمه فصل 19 فهرست بها | I28: 361/4 | K28: متر مربع | P28: 569.1511
B31: پیمانکار | F31: دستگاه نظارت | J31: کار فرما
B35: منبع مدرک: کارفرما ناظر مقیم پروژه امور قرارداد ها بایگانی دستگاه نظارت پیمانکار

Sheet  المان PNT-G-132
G2: شماره صورتمجلس PNT-G-132
B4: موضـوع:اضافه بها اعمال رنگ High Solid GLASS FLAKE EPOXY به وسیله دستگاه رنگ پاش بدون هوا (Airless) به ضخامت 250 میکرون درناحیه بالای اسپلش زون تا زیر عرشه اسکله معادل 20% بهای واحد ردیف 641903107 طبق بند 13 مقدمه فصل 19 فهرست بها
B5: موقعیت: محورهای 19 الی 45
B6: ردیف | C6: شرح | H6: سطح واحد(m2) | I6: تعداد | J6: طول/ابعاد (mm) | K6: طول/ابعاد موثر (mm) | L6: همپوشانی یک المان (m2) | M6: سطح یک المان(m2) | N6: سطح کل(m2)
B7: 1 | C7: S19-45(lower) AXIS 25 ROW C~E | G7: UC313*308*20*15 | H7: 1.828 | I7: 1 | J7: =6096*2 -> 12192 | K7: =6096*2 -> 12192 | L7: =2*0.85*0.308+2*1.9*0.308 -> 1.694 | M7: =K7*H7/1000 -> 22.286976 | N7: =ROUND(M7*I7-I7*L7,1) -> 20.6 | AL7: REPORT 119 - FINISH COAT
B8: 2 | C8: S19-45 (upper) AXIS 25 ROW C~E | G8: UC313*308*20*15 | H8: 1.828 | I8: 1 | J8: =6096*2 -> 12192 | K8: =6096*2 -> 12192 | L8: =2*0.85*0.308 -> 0.5236 | M8: =K8*H8/1000 -> 22.286976 | N8: =ROUND(M8*I8-I8*L8,1) -> 21.8
B9: 3 | C9: S25-08 | G9: UC220*210*12*8 | H9: 1.284 | I9: 1 | J9: 1510 | K9: 1510 | L9: 0 | M9: =H9*K9/1000 -> 1.93884 | N9: =ROUND(M9*I9-I9*L9,1) -> 1.9
B10: 4 | C10: S25-03 | G10: UC160*160*12*8 | H10: 0.944 | I10: 5 | J10: 1510 | K10: 1510 | L10: 0 | M10: =H10*K10/1000 -> 1.42544 | N10: =ROUND(M10*I10-I10*L10,1) -> 7.1
B11: 5 | C11: S25-02 | G11: UC160*160*12*8 | H11: 0.944 | I11: 6 | J11: 2402 | K11: 2251 | L11: 0 | M11: =H11*K11/1000 -> 2.124944 | N11: =ROUND(M11*I11-I11*L11,1) -> 12.7
B12: 6 | C12: S-24-06-U | G12: UC200*210*12*10 | H12: 1.22 | I12: 2 | J12: 3909 | K12: 3847 | L12: =0.126+0.114 -> 0.24 | M12: =H12*K12/1000 -> 4.69334 | N12: =ROUND(M12*I12-I12*L12,1) -> 8.9
B13: 7 | C13: S-24-02-U | G13: UC200*210*12*10 | H13: 1.22 | I13: 2 | J13: 7829 | K13: 7829 | L13: =0.252+0.1088 -> 0.3608 | M13: =H13*K13/1000 -> 9.55138 | N13: =ROUND(M13*I13-I13*L13,1) -> 18.4
B14: 8 | C14: S-24-07-U | G14: UC200*210*12*10 | H14: 1.22 | I14: 2 | J14: 3659 | K14: 3569 | L14: =0.126+0.114 -> 0.24 | M14: =H14*K14/1000 -> 4.35418 | N14: =ROUND(M14*I14-I14*L14,1) -> 8.2
B15: 9 | C15: S-24-06-L | G15: UC200*210*12*10 | H15: 1.22 | I15: 2 | J15: 3909 | K15: 3847 | L15: =0.126+0.114 -> 0.24 | M15: =H15*K15/1000 -> 4.69334 | N15: =ROUND(M15*I15-I15*L15,1) -> 8.9
B16: 10 | C16: S-24-02-L | G16: UC200*210*12*10 | H16: 1.22 | I16: 2 | J16: 7829 | K16: 7829 | L16: 0.252 | M16: =H16*K16/1000 -> 9.55138 | N16: =ROUND(M16*I16-I16*L16,1) -> 18.6
B17: 11 | C17: S-24-07-L | G17: UC200*210*12*10 | H17: 1.22 | I17: 2 | J17: 3659 | K17: 3569 | L17: =0.126+0.114 -> 0.24 | M17: =H17*K17/1000 -> 4.35418 | N17: =ROUND(M17*I17-I17*L17,1) -> 8.2
B18: 12 | C18: S-24-03-U | G18: UC200*210*12*10 | H18: 1.22 | I18: 2 | J18: 5486 | K18: 5486 | L18: 0.126 | M18: =H18*K18/1000 -> 6.69292 | N18: =ROUND(M18*I18-I18*L18,1) -> 13.1
B19: 13 | C19: S-24-03-L | G19: UC200*210*12*10 | H19: 1.22 | I19: 2 | J19: 5486 | K19: 5486 | L19: 0.15834 | M19: =H19*K19/1000 -> 6.69292 | N19: =ROUND(M19*I19-I19*L19,1) -> 13.1
B20: 14 | C20: S24-C-03 | G20: UC160*160*12*8 | H20: 0.944 | I20: 2 | J20: 2948 | K20: 2771 | L20: 0 | M20: =ROUNDUP(H20*K20/1000,1) -> 2.7 | N20: =M20*I20-L20*I20 -> 5.4
B21: 15 | C21: S24-C-04 | G21: UC160*160*12*8 | H21: 0.944 | I21: 1 | J21: 1629 | K21: 1629 | L21: 0 | M21: =ROUNDUP(H21*K21/1000,1) -> 1.6 | N21: =M21*I21-L21*I21 -> 1.6
B22: 16 | C22: BOX TO PILE (AXIS-25 ROW C & D) | G22: 1920*720 | H22: 3.58 | I22: 2 | J22: - | K22: - | L22: =1.9*0.308 -> 0.5852 | M22: =H22 -> 3.58 | N22: =ROUND(M22*I22-L22*I22,1) -> 6
B23: 17 | C23: GUSSET - LOWER DECK (Row C) AXIS 25 | G23: TYP.05 (LOWER DECK) | H23: 2.042 | I23: 1 | J23: - | K23: - | L23: =0.85*0.308+6*2*0.3*0.21 -> 1.0178 | M23: =H23*I23 -> 2.042 | N23: =ROUND(M23*I23-I23*L23,1) -> 1
B24: 18 | C24: GUSSET - UPPER DECK (Row C) AXIS 25 | G24: TYP.9 (UPPER DECK) | H24: 1.895172 | I24: 1 | J24: - | K24: - | L24: 0.751525 | M24: =H24*I24 -> 1.895172 | N24: =ROUND(M24*I24-I24*L24,1) -> 1.1
B25: 19 | C25: GUSSET - LOWER DECK (Row D) AXIS 25 | G25: TYP.04 (LOWER DECK) | H25: 2.042 | I25: 1 | J25: - | K25: - | L25: =0.85*0.308+6*2*0.3*0.21 -> 1.0178 | M25: =H25*I25 -> 2.042 | N25: =ROUND(M25*I25-I25*L25,1) -> 1
B26: 20 | C26: GUSSET - UPPER DECK (Row D) AXIS 25 | G26: TYP.9 (UPPER DECK) | H26: 1.895172 | I26: 1 | J26: - | K26: - | L26: 0.751525 | M26: =H26*I26 -> 1.895172 | N26: =ROUND(M26*I26-I26*L26,1) -> 1.1
B27: 21 | C27: GUSSET - LOWER DECK (Row C~D) AXIS 24~25 | G27: TYP.12 (LOWER DECK) | H27: 0.835 | I27: 1 | J27: - | K27: - | L27: 0.3368 | M27: =H27*I27 -> 0.835 | N27: =ROUND(M27*I27-I27*L27,1) -> 0.5
B28: 22 | C28: GUSSET - UPPER DECK (Row C~D) AXIS 24~25 | G28: TYP.08 (UPPER DECK) | H28: =H27 -> 0.835 | I28: 1 | J28: - | K28: - | L28: =L27 -> 0.3368 | M28: =H28*I28 -> 0.835 | N28: =ROUND(M28*I28-I28*L28,1) -> 0.5
B29: 23 | C29: GUSSET - LOWER DECK (Row D~E) AXIS 24~25 | G29: TYP.12 (LOWER DECK) | H29: 0.835 | I29: 1 | J29: - | K29: - | L29: 0.3368 | M29: =H29*I29 -> 0.835 | N29: =ROUND(M29*I29-I29*L29,1) -> 0.5
B30: 24 | C30: GUSSET - UPPER DECK (Row D~E) AXIS 24~25 | G30: TYP.08 (UPPER DECK) | H30: =H29 -> 0.835 | I30: 1 | J30: - | K30: - | L30: =L29 -> 0.3368 | M30: =H30*I30 -> 0.835 | N30: =ROUND(M30*I30-I30*L30,1) -> 0.5
B31: جمع کل | N31: =SUM(N7:N30) -> 180.7
B32: جمع کل دو لایه | N32: =N31*2 -> 361.4
B33: پیمانکار : تاریخ : | I33: دستگاه نظارت : تاریخ :
B35: منبع مدرک: کارفرما ناظر مقیم پروژه امور قرارداد ها بایگانی دستگاه نظارت پیمانکار

Sheet PNT-G-131
B1: صورت مجلس | E1: شماره ویرایش مدرک: | H1: تاریخ ویرایش مدرک: | K1: EC-01-F-09
F4: صورتمجلس
B11: نام پروژه: تعمیرات اساسی ضلع جنوبی اسکله شرقی جزیره خارگ ازمحور19الی45 (PC) | F11: شماره صورت PNT-G-131 | J11: تاریخ :1404/07/28
B14: نام پیمانکار: شرکت صنایع فرا ساحل (صف) | F14: شماره قرارداد: 11048-73-38 | J14: تعداد صفحات پيوست: 4 صفحه
B17: موضـوع: اضافه بهای اعمال رنگ High Solid GLASS FLAKE EPOXY به وسیله دستگاه رنگ پاش بدون هوا (Airless) به ضخامت 250 میکرون در اسکله ( در صورتی که سطح مورد نظر ، لوله تا 8 اینچ یا مقاطع فولادی تا 200 میلی متر باشد.)
B20: بدینوسیله امضا کنندگان ذیل تایید می نمایند , عملیات اعمال رنگ High Solid GLASS FLAKE EPOXY به وسیله دستگاه رنگ پاش بدون هوا (Airless) به ضخامت 250 میکرون در اسکله بر روی المان های ناحیه حد فاصل محور های 19 الی 45 ضلع جنوبی اسکله شرقی مطابق با ریزمتره پیوست به مساحت 248/4 متر مربع انجام گردید.
B26: ردیف | C26: ردیف فهرست بها | E26: شرح | I26: مقدار | K26: واحد
B28: 21 | C28: 641903122 | E28: اضافه بهای اعمال رنگ High Solid GLASS FLAKE EPOXY به وسیله دستگاه رنگ پاش بدون هوا (Airless) به ضخامت 250 میکرون در اسکله ( در صورتی که سطح مورد نظر ، لوله تا 8 اینچ یا مقاطع فولادی تا 200 میلی متر باشد.) | I28: 248/4 | K28: متر مربع
B31: پیمانکار | F31: دستگاه نظارت | J31: کار فرما
B35: منبع مدرک: کارفرما ناظر مقیم پروژه امور قرارداد ها بایگانی دستگاه نظارت پیمانکار

Sheet  المان PNT-G-131
G2: شماره صورتمجلس PNT-G-131
B4: موضـوع: اضافه بهای اعمال رنگ High Solid GLASS FLAKE Epoxy به وسیله دستگاه رنگ پاش بدون هوا (Airless) به ضخامت 250 میکرون در اسکله ( در صورتی که سطح مورد نظر ، لوله تا 8 اینچ یا مقاطع فولادی تا 200 میلی متر باشد.)
B5: موقعیت: محورهای 19 الی 45
B6: ردیف | C6: شرح | H6: سطح واحد(m2) | I6: تعداد | J6: طول/ابعاد (mm) | K6: طول/ابعاد موثر (mm) | L6: همپوشانی یک المان (m2) | M6: سطح یک المان(m2) | N6: سطح کل(m2)
B7: 1 | C7: S19-45(lower) AXIS 25 ROW C~E | G7: UC313*308*20*15 | H7: 1.828 | I7: 0 | J7: =6096*2 -> 12192 | K7: =6096*2 -> 12192 | L7: =2*0.85*0.308+2*1.9*0.308 -> 1.694 | M7: =K7*H7/1000 -> 22.286976 | N7: =ROUND(M7*I7-I7*L7,1) -> 0 | AL7: REPORT 119 - FINISH COAT
B8: 2 | C8: S19-45 (upper) AXIS 25 ROW C~E | G8: UC313*308*20*15 | H8: 1.828 | I8: 0 | J8: =6096*2 -> 12192 | K8: =6096*2 -> 12192 | L8: =2*0.85*0.308 -> 0.5236 | M8: =K8*H8/1000 -> 22.286976 | N8: =ROUND(M8*I8-I8*L8,1) -> 0
B9: 3 | C9: S25-08 | G9: UC220*210*12*8 | H9: 1.284 | I9: 0 | J9: 1510 | K9: 1510 | L9: 0 | M9: =H9*K9/1000 -> 1.93884 | N9: =ROUND(M9*I9-I9*L9,1) -> 0
B10: 4 | C10: S25-03 | G10: UC160*160*12*8 | H10: 0.944 | I10: 5 | J10: 1510 | K10: 1510 | L10: 0 | M10: =H10*K10/1000 -> 1.42544 | N10: =ROUND(M10*I10-I10*L10,1) -> 7.1
B11: 5 | C11: S25-02 | G11: UC160*160*12*8 | H11: 0.944 | I11: 6 | J11: 2402 | K11: 2251 | L11: 0 | M11: =H11*K11/1000 -> 2.124944 | N11: =ROUND(M11*I11-I11*L11,1) -> 12.7
B12: 6 | C12: S-24-06-U | G12: UC200*210*12*10 | H12: 1.22 | I12: 2 | J12: 3909 | K12: 3847 | L12: =0.126+0.114 -> 0.24 | M12: =H12*K12/1000 -> 4.69334 | N12: =ROUND(M12*I12-I12*L12,1) -> 8.9
B13: 7 | C13: S-24-02-U | G13: UC200*210*12*10 | H13: 1.22 | I13: 2 | J13: 7829 | K13: 7829 | L13: =0.252+0.1088 -> 0.3608 | M13: =H13*K13/1000 -> 9.55138 | N13: =ROUND(M13*I13-I13*L13,1) -> 18.4
B14: 8 | C14: S-24-07-U | G14: UC200*210*12*10 | H14: 1.22 | I14: 2 | J14: 3659 | K14: 3569 | L14: =0.126+0.114 -> 0.24 | M14: =H14*K14/1000 -> 4.35418 | N14: =ROUND(M14*I14-I14*L14,1) -> 8.2
B15: 9 | C15: S-24-06-L | G15: UC200*210*12*10 | H15: 1.22 | I15: 2 | J15: 3909 | K15: 3847 | L15: =0.126+0.114 -> 0.24 | M15: =H15*K15/1000 -> 4.69334 | N15: =ROUND(M15*I15-I15*L15,1) -> 8.9
B16: 10 | C16: S-24-02-L | G16: UC200*210*12*10 | H16: 1.22 | I16: 2 | J16: 7829 | K16: 7829 | L16: 0.252 | M16: =H16*K16/1000 -> 9.55138 | N16: =ROUND(M16*I16-I16*L16,1) -> 18.6
B17: 11 | C17: S-24-07-L | G17: UC200*210*12*10 | H17: 1.22 | I17: 2 | J17: 3659 | K17: 3569 | L17: =0.126+0.114 -> 0.24 | M17: =H17*K17/1000 -> 4.35418 | N17: =ROUND(M17*I17-I17*L17,1) -> 8.2
B18: 12 | C18: S-24-03-U | G18: UC200*210*12*10 | H18: 1.22 | I18: 2 | J18: 5486 | K18: 5486 | L18: 0.126 | M18: =H18*K18/1000 -> 6.69292 | N18: =ROUND(M18*I18-I18*L18,1) -> 13.1
B19: 13 | C19: S-24-03-L | G19: UC200*210*12*10 | H19: 1.22 | I19: 2 | J19: 5486 | K19: 5486 | L19: 0.15834 | M19: =H19*K19/1000 -> 6.69292 | N19: =ROUND(M19*I19-I19*L19,1) -> 13.1
B20: 14 | C20: S24-C-03 | G20: UC160*160*12*8 | H20: 0.944 | I20: 2 | J20: 2948 | K20: 2771 | L20: 0 | M20: =ROUNDUP(H20*K20/1000,1) -> 2.7 | N20: =M20*I20-L20*I20 -> 5.4
B21: 15 | C21: S24-C-04 | G21: UC160*160*12*8 | H21: 0.944 | I21: 1 | J21: 1629 | K21: 1629 | L21: 0 | M21: =ROUNDUP(H21*K21/1000,1) -> 1.6 | N21: =M21*I21-L21*I21 -> 1.6
B22: 16 | C22: BOX TO PILE (AXIS-25 ROW C & D) | G22: 1920*720 | H22: 3.58 | I22: 0 | J22: - | K22: - | L22: =1.9*0.308 -> 0.5852 | M22: =H22 -> 3.58 | N22: =ROUND(M22*I22-L22*I22,1) -> 0
B23: 17 | C23: GUSSET - LOWER DECK (Row C) AXIS 25 | G23: TYP.05 (LOWER DECK) | H23: 2.042 | I23: 0 | J23: - | K23: - | L23: =0.85*0.308+6*2*0.3*0.21 -> 1.0178 | M23: =H23*I23 -> 0 | N23: =ROUND(M23*I23-I23*L23,1) -> 0
B24: 18 | C24: GUSSET - UPPER DECK (Row C) AXIS 25 | G24: TYP.9 (UPPER DECK) | H24: 1.895172 | I24: 0 | J24: - | K24: - | L24: 0.751525 | M24: =H24*I24 -> 0 | N24: =ROUND(M24*I24-I24*L24,1) -> 0
B25: 19 | C25: GUSSET - LOWER DECK (Row D) AXIS 25 | G25: TYP.04 (LOWER DECK) | H25: 2.042 | I25: 0 | J25: - | K25: - | L25: =0.85*0.308+6*2*0.3*0.21 -> 1.0178 | M25: =H25*I25 -> 0 | N25: =ROUND(M25*I25-I25*L25,1) -> 0
B26: 20 | C26: GUSSET - UPPER DECK (Row D) AXIS 25 | G26: TYP.9 (UPPER DECK) | H26: 1.895172 | I26: 0 | J26: - | K26: - | L26: 0.751525 | M26: =H26*I26 -> 0 | N26: =ROUND(M26*I26-I26*L26,1) -> 0
B27: 21 | C27: GUSSET - LOWER DECK (Row C~D) AXIS 24~25 | G27: TYP.12 (LOWER DECK) | H27: 0.835 | I27: 0 | J27: - | K27: - | L27: 0.3368 | M27: =H27*I27 -> 0 | N27: =ROUND(M27*I27-I27*L27,1) -> 0
B28: 22 | C28: GUSSET - UPPER DECK (Row C~D) AXIS 24~25 | G28: TYP.08 (UPPER DECK) | H28: =H27 -> 0.835 | I28: 0 | J28: - | K28: - | L28: =L27 -> 0.3368 | M28: =H28*I28 -> 0 | N28: =ROUND(M28*I28-I28*L28,1) -> 0
B29: 23 | C29: GUSSET - LOWER DECK (Row D~E) AXIS 24~25 | G29: TYP.12 (LOWER DECK) | H29: 0.835 | I29: 0 | J29: - | K29: - | L29: 0.3368 | M29: =H29*I29 -> 0 | N29: =ROUND(M29*I29-I29*L29,1) -> 0
B30: 24 | C30: GUSSET - UPPER DECK (Row D~E) AXIS 24~25 | G30: TYP.08 (UPPER DECK) | H30: =H29 -> 0.835 | I30: 0 | J30: - | K30: - | L30: =L29 -> 0.3368 | M30: =H30*I30 -> 0 | N30: =ROUND(M30*I30-I30*L30,1) -> 0
B31: جمع کل | N31: =SUM(N7:N30) -> 124.2
B32: جمع کل دو لایه | N32: =N31*2 -> 248.4
B33: پیمانکار : تاریخ : | I33: دستگاه نظارت : تاریخ :
B35: منبع مدرک: کارفرما ناظر مقیم پروژه امور قرارداد ها بایگانی دستگاه نظارت پیمانکار

Sheet PNT-G-130
B1: صورت مجلس | E1: شماره ویرایش مدرک: | H1: تاریخ ویرایش مدرک: | K1: EC-01-F-09
F4: صورتمجلس
B11: نام پروژه: تعمیرات اساسی ضلع جنوبی اسکله شرقی جزیره خارگ ازمحور19الی45 (PC) | F11: شماره صورت PNT-G-130 | J11: تاریخ :1404/07/28
B14: نام پیمانکار: شرکت صنایع فرا ساحل (صف) | F14: شماره قرارداد: 11048-73-38 | J14: تعداد صفحات پيوست: 4 صفحه
B17: موضـوع: اعمال رنگ High Solid GLASS FLAKE EPOXY به وسیله دستگاه رنگ پاش بدون هوا (Airless) به ضخامت 250 میکرون در اسکله
B20: بدینوسیله امضا کنندگان ذیل تایید می نمایند , عملیات اعمال رنگ High Solid GLASS FLAKE EPOXY به وسیله دستگاه رنگ پاش بدون هوا (Airless) به ضخامت 250 میکرون در اسکله بر روی المان های ناحیه حد فاصل محور های 19 الی 45 ضلع جنوبی اسکله شرقی مطابق با ریزمتره پیوست به مساحت 361/4 متر مربع انجام گردید.
B26: ردیف | C26: ردیف فهرست بها | E26: شرح | I26: مقدار | K26: واحد
B28: 17 | C28: 641903107 | E28: اعمال رنگ High Solid GLASS FLAKE EPOXY به وسیله دستگاه رنگ پاش بدون هوا (Airless) به ضخامت 250 میکرون در اسکله | I28: 361/4 | K28: متر مربع
B31: پیمانکار | F31: دستگاه نظارت | J31: کار فرما
B35: منبع مدرک: کارفرما ناظر مقیم پروژه امور قرارداد ها بایگانی دستگاه نظارت پیمانکار

Sheet  المان PNT-G-130
G2: شماره صورتمجلس PNT-G-130
B4: موضـوع: اعمال رنگ High Solid GLASS FLAKE EPOXY به وسیله دستگاه رنگ پاش بدون هوا (Airless) به ضخامت 250 میکرون در اسکله
B5: موقعیت: محورهای 19 الی 45
B6: ردیف | C6: شرح | H6: سطح واحد(m2) | I6: تعداد | J6: طول/ابعاد (mm) | K6: طول/ابعاد موثر (mm) | L6: همپوشانی یک المان (m2) | M6: سطح یک المان(m2) | N6: سطح کل(m2)
B7: 1 | C7: S19-45(lower) AXIS 25 ROW C~E | G7: UC313*308*20*15 | H7: 1.828 | I7: 1 | J7: =6096*2 -> 12192 | K7: =6096*2 -> 12192 | L7: =2*0.85*0.308+2*1.9*0.308 -> 1.694 | M7: =K7*H7/1000 -> 22.286976 | N7: =ROUND(M7*I7-I7*L7,1) -> 20.6 | AL7: REPORT 119 - FINISH COAT
B8: 2 | C8: S19-45 (upper) AXIS 25 ROW C~E | G8: UC313*308*20*15 | H8: 1.828 | I8: 1 | J8: =6096*2 -> 12192 | K8: =6096*2 -> 12192 | L8: =2*0.85*0.308 -> 0.5236 | M8: =K8*H8/1000 -> 22.286976 | N8: =ROUND(M8*I8-I8*L8,1) -> 21.8
B9: 3 | C9: S25-08 | G9: UC220*210*12*8 | H9: 1.284 | I9: 1 | J9: 1510 | K9: 1510 | L9: 0 | M9: =H9*K9/1000 -> 1.93884 | N9: =ROUND(M9*I9-I9*L9,1) -> 1.9
B10: 4 | C10: S25-03 | G10: UC160*160*12*8 | H10: 0.944 | I10: 5 | J10: 1510 | K10: 1510 | L10: 0 | M10: =H10*K10/1000 -> 1.42544 | N10: =ROUND(M10*I10-I10*L10,1) -> 7.1
B11: 5 | C11: S25-02 | G11: UC160*160*12*8 | H11: 0.944 | I11: 6 | J11: 2402 | K11: 2251 | L11: 0 | M11: =H11*K11/1000 -> 2.124944 | N11: =ROUND(M11*I11-I11*L11,1) -> 12.7
B12: 6 | C12: S-24-06-U | G12: UC200*210*12*10 | H12: 1.22 | I12: 2 | J12: 3909 | K12: 3847 | L12: =0.126+0.114 -> 0.24 | M12: =H12*K12/1000 -> 4.69334 | N12: =ROUND(M12*I12-I12*L12,1) -> 8.9
B13: 7 | C13: S-24-02-U | G13: UC200*210*12*10 | H13: 1.22 | I13: 2 | J13: 7829 | K13: 7829 | L13: =0.252+0.1088 -> 0.3608 | M13: =H13*K13/1000 -> 9.55138 | N13: =ROUND(M13*I13-I13*L13,1) -> 18.4
B14: 8 | C14: S-24-07-U | G14: UC200*210*12*10 | H14: 1.22 | I14: 2 | J14: 3659 | K14: 3569 | L14: =0.126+0.114 -> 0.24 | M14: =H14*K14/1000 -> 4.35418 | N14: =ROUND(M14*I14-I14*L14,1) -> 8.2
B15: 9 | C15: S-24-06-L | G15: UC200*210*12*10 | H15: 1.22 | I15: 2 | J15: 3909 | K15: 3847 | L15: =0.126+0.114 -> 0.24 | M15: =H15*K15/1000 -> 4.69334 | N15: =ROUND(M15*I15-I15*L15,1) -> 8.9
B16: 10 | C16: S-24-02-L | G16: UC200*210*12*10 | H16: 1.22 | I16: 2 | J16: 7829 | K16: 7829 | L16: 0.252 | M16: =H16*K16/1000 -> 9.55138 | N16: =ROUND(M16*I16-I16*L16,1) -> 18.6
B17: 11 | C17: S-24-07-L | G17: UC200*210*12*10 | H17: 1.22 | I17: 2 | J17: 3659 | K17: 3569 | L17: =0.126+0.114 -> 0.24 | M17: =H17*K17/1000 -> 4.35418 | N17: =ROUND(M17*I17-I17*L17,1) -> 8.2
B18: 12 | C18: S-24-03-U | G18: UC200*210*12*10 | H18: 1.22 | I18: 2 | J18: 5486 | K18: 5486 | L18: 0.126 | M18: =H18*K18/1000 -> 6.69292 | N18: =ROUND(M18*I18-I18*L18,1) -> 13.1
B19: 13 | C19: S-24-03-L | G19: UC200*210*12*10 | H19: 1.22 | I19: 2 | J19: 5486 | K19: 5486 | L19: 0.15834 | M19: =H19*K19/1000 -> 6.69292 | N19: =ROUND(M19*I19-I19*L19,1) -> 13.1
B20: 14 | C20: S24-C-03 | G20: UC160*160*12*8 | H20: 0.944 | I20: 2 | J20: 2948 | K20: 2771 | L20: 0 | M20: =ROUNDUP(H20*K20/1000,1) -> 2.7 | N20: =M20*I20-L20*I20 -> 5.4
B21: 15 | C21: S24-C-04 | G21: UC160*160*12*8 | H21: 0.944 | I21: 1 | J21: 1629 | K21: 1629 | L21: 0 | M21: =ROUNDUP(H21*K21/1000,1) -> 1.6 | N21: =M21*I21-L21*I21 -> 1.6
B22: 16 | C22: BOX TO PILE (AXIS-25 ROW C & D) | G22: 1920*720 | H22: 3.58 | I22: 2 | J22: - | K22: - | L22: =1.9*0.308 -> 0.5852 | M22: =H22 -> 3.58 | N22: =ROUND(M22*I22-L22*I22,1) -> 6
B23: 17 | C23: GUSSET - LOWER DECK (Row C) AXIS 25 | G23: TYP.05 (LOWER DECK) | H23: 2.042 | I23: 1 | J23: - | K23: - | L23: =0.85*0.308+6*2*0.3*0.21 -> 1.0178 | M23: =H23*I23 -> 2.042 | N23: =ROUND(M23*I23-I23*L23,1) -> 1
B24: 18 | C24: GUSSET - UPPER DECK (Row C) AXIS 25 | G24: TYP.9 (UPPER DECK) | H24: 1.895172 | I24: 1 | J24: - | K24: - | L24: 0.751525 | M24: =H24*I24 -> 1.895172 | N24: =ROUND(M24*I24-I24*L24,1) -> 1.1
B25: 19 | C25: GUSSET - LOWER DECK (Row D) AXIS 25 | G25: TYP.04 (LOWER DECK) | H25: 2.042 | I25: 1 | J25: - | K25: - | L25: =0.85*0.308+6*2*0.3*0.21 -> 1.0178 | M25: =H25*I25 -> 2.042 | N25: =ROUND(M25*I25-I25*L25,1) -> 1
B26: 20 | C26: GUSSET - UPPER DECK (Row D) AXIS 25 | G26: TYP.9 (UPPER DECK) | H26: 1.895172 | I26: 1 | J26: - | K26: - | L26: 0.751525 | M26: =H26*I26 -> 1.895172 | N26: =ROUND(M26*I26-I26*L26,1) -> 1.1
B27: 21 | C27: GUSSET - LOWER DECK (Row C~D) AXIS 24~25 | G27: TYP.12 (LOWER DECK) | H27: 0.835 | I27: 1 | J27: - | K27: - | L27: 0.3368 | M27: =H27*I27 -> 0.835 | N27: =ROUND(M27*I27-I27*L27,1) -> 0.5
B28: 22 | C28: GUSSET - UPPER DECK (Row C~D) AXIS 24~25 | G28: TYP.08 (UPPER DECK) | H28: =H27 -> 0.835 | I28: 1 | J28: - | K28: - | L28: =L27 -> 0.3368 | M28: =H28*I28 -> 0.835 | N28: =ROUND(M28*I28-I28*L28,1) -> 0.5
B29: 23 | C29: GUSSET - LOWER DECK (Row D~E) AXIS 24~25 | G29: TYP.12 (LOWER DECK) | H29: 0.835 | I29: 1 | J29: - | K29: - | L29: 0.3368 | M29: =H29*I29 -> 0.835 | N29: =ROUND(M29*I29-I29*L29,1) -> 0.5
B30: 24 | C30: GUSSET - UPPER DECK (Row D~E) AXIS 24~25 | G30: TYP.08 (UPPER DECK) | H30: =H29 -> 0.835 | I30: 1 | J30: - | K30: - | L30: =L29 -> 0.3368 | M30: =H30*I30 -> 0.835 | N30: =ROUND(M30*I30-I30*L30,1) -> 0.5
B31: جمع کل | N31: =SUM(N7:N30) -> 180.7
B32: جمع کل دو لایه | N32: =N31*2 -> 361.4
B33: پیمانکار : تاریخ : | I33: دستگاه نظارت : تاریخ :
B35: منبع مدرک: کارفرما ناظر مقیم پروژه امور قرارداد ها بایگانی دستگاه نظارت پیمانکار

Sheet PNT-G-129
B1: صورت مجلس | E1: شماره ویرایش مدرک: | H1: تاریخ ویرایش مدرک: | K1: EC-01-F-09
F4: صورتمجلس
B11: نام پروژه: تعمیرات اساسی ضلع جنوبی اسکله شرقی جزیره خارگ ازمحور19الی45 (PC) | F11: شماره صورتمجلس PNT-G-129 | J11: تاریخ :1404/07/28
B14: نام پیمانکار: شرکت صنایع فرا ساحل (صف) | F14: شماره قرارداد: 11048-73-38 | J14: تعداد صفحات پيوست: 6 صفحه
B17: موضـوع: تهیه رنگ High Solid GLASS FLAKE EPOXY به ضخامت 250 میکرون
B20: بدینوسیله امضا کنندگان ذیل تایید می نمایند , تهیه رنگ High Solid GLASS FLAKE EPOXY به ضخامت 250 میکرون برای المان های ناحیه حد فاصل محور های 19 الی 45 ضلع جنوبی اسکله شرقی مطابق با ریزمتره پیوست به مساحت 655/0 متر مربع انجام گردید.
B26: ردیف | C26: ردیف فهرست بها | E26: شرح | I26: مقدار | K26: واحد
B28: 28 | C28: 641904105 | E28: تهیه رنگ High Solid GLASS FLAKE EPOXY به ضخامت 250 میکرون | I28: 655/0 | K28: متر مربع
B31: پیمانکار | F31: دستگاه نظارت | J31: کار فرما
B35: منبع مدرک: کارفرما ناظر مقیم پروژه امور قرارداد ها بایگانی دستگاه نظارت پیمانکار

Sheet PNT-G-128
B1: صورت مجلس | E1: شماره ویرایش مدرک: | H1: تاریخ ویرایش مدرک: | K1: EC-01-F-09
F4: صورتمجلس
B11: نام پروژه: تعمیرات اساسی ضلع جنوبی اسکله شرقی جزیره خارگ ازمحور19الی45 (PC) | F11: شماره صورت PNT-G-128 | J11: تاریخ :1404/07/28
B14: نام پیمانکار: شرکت صنایع فرا ساحل (صف) | F14: شماره قرارداد: 11048-73-38 | J14: تعداد صفحات پيوست: 5 صفحه
B17: موضـوع: اضافه بها اعمال رنگ High Solid GLASS FLAKE EPOXY به وسیله دستگاه رنگ پاش بدون هوا (Airless) به ضخامت 250 میکرون درناحیه بالای اسپلش زون تا زیر عرشه اسکله معادل 20% بهای واحد ردیف 641903107 طبق بند 13 مقدمه فصل 19 فهرست بها
B20: بدینوسیله امضا کنندگان ذیل تایید می نمایند , عملیات اعمال رنگ High Solid GLASS FLAKE EPOXY به وسیله دستگاه رنگ پاش بدون هوا (Airless) به ضخامت 250 میکرون در درناحیه بالای اسپلش زون تا زیر عرشه اسکله بر روی المان های ناحیه حد فاصل محور های 19 الی 45 ضلع جنوبی اسکله شرقی مطابق با ریزمتره پیوست به مساحت 655/0 متر مربع انجام گردید.
B26: ردیف | C26: ردیف فهرست بها | E26: شرح | I26: مقدار | K26: واحد
B28: 24 | C28: 641903132* | E28: اضافه بها اعمال رنگ High Solid GLASS FLAKE EPOXY به وسیله دستگاه رنگ پاش بدون هوا (Airless) به ضخامت 250 میکرون درناحیه بالای اسپلش زون تا زیر عرشه اسکله معادل 20% بهای واحد ردیف 641903107 طبق بند 13 مقدمه فصل 19 فهرست بها | I28: 655/0 | K28: متر مربع | P28: 569.1511
B31: پیمانکار | F31: دستگاه نظارت | J31: کار فرما
B35: منبع مدرک: کارفرما ناظر مقیم پروژه امور قرارداد ها بایگانی دستگاه نظارت پیمانکار

Sheet  المان PNT-G-128
G2: شماره صورتمجلس PNT-G-128
B4: موضـوع:اضافه بها اعمال رنگ High Solid GLASS FLAKE EPOXY به وسیله دستگاه رنگ پاش بدون هوا (Airless) به ضخامت 250 میکرون درناحیه بالای اسپلش زون تا زیر عرشه اسکله معادل 20% بهای واحد ردیف 641903107 طبق بند 13 مقدمه فصل 19 فهرست بها
B5: موقعیت: محورهای 19 الی 45
B6: ردیف | C6: شرح | H6: سطح واحد(m2) | I6: تعداد | J6: طول/ابعاد (mm) | K6: طول/ابعاد موثر (mm) | L6: همپوشانی یک المان (m2) | M6: سطح یک المان(m2) | N6: سطح کل(m2)
B7: 1 | C7: S36-02 | G7: UC160*160*12*8 | H7: 0.944 | I7: 5 | J7: 2383 | K7: 2238 | L7: 0 | M7: =H7*K7/1000 -> 2.112672 | N7: =ROUND(M7*I7-I7*L7,1) -> 10.6 | AC7: REPORT 116 - FINISH COAT
B8: 2 | C8: S42-03 | G8: UC160*160*12*8 | H8: 0.944 | I8: 3 | J8: 1510 | K8: 1510 | L8: 0 | M8: =H8*K8/1000 -> 1.42544 | N8: =ROUND(M8*I8-I8*L8,1) -> 4.3 | AC8: REPORT 117 - FINISH COAT
B9: 3 | C9: S39-05 | G9: UC160*160*12*8 | H9: 0.944 | I9: 1 | J9: 1817 | K9: 1735 | L9: 0 | M9: =ROUNDUP(H9*K9/1000,2) -> 1.64 | N9: =M9*I9-L9*I9 -> 1.64 | AC9: REPORT 118 - FINISH COAT
B10: 4 | C10: S38-02 | G10: UC160*160*12*8 | H10: 0.944 | I10: 5 | J10: 2402 | K10: 2251 | L10: 0 | M10: =H10*K10/1000 -> 2.124944 | N10: =ROUND(M10*I10-I10*L10,1) -> 10.6
B11: 5 | C11: S35-02 | G11: UC160*160*12*8 | H11: 0.944 | I11: 1 | J11: 2383 | K11: 2238 | L11: 0 | M11: =H11*K11/1000 -> 2.112672 | N11: =ROUND(M11*I11-I11*L11,1) -> 2.1
B12: 6 | C12: S34-02 | G12: UC160*160*12*8 | H12: 0.944 | I12: 1 | J12: 2402 | K12: 2251 | L12: 0 | M12: =H12*K12/1000 -> 2.124944 | N12: =ROUND(M12*I12-I12*L12,1) -> 2.1
B13: 7 | C13: S41-03 | G13: UC160*160*12*8 | H13: 0.944 | I13: 2 | J13: 1510 | K13: 1510 | L13: 0 | M13: =H13*K13/1000 -> 1.42544 | N13: =ROUND(M13*I13-I13*L13,1) -> 2.9
B14: 8 | C14: S35-05 | G14: UC160*160*12*8 | H14: 0.944 | I14: 1 | J14: 1817 | K14: 1735 | L14: 0 | M14: =H14*K14/1000 -> 1.63784 | N14: =ROUND(M14*I14-I14*L14,1) -> 1.6
B15: 9 | C15: S45-02A | G15: UC220*210*12*8 | H15: 1.284 | I15: 1 | J15: 2446 | K15: 2229 | L15: 0 | M15: =H15*K15/1000 -> 2.862036 | N15: =ROUND(M15*I15-I15*L15,1) -> 2.9
B16: 10 | C16: S36-03 | G16: UC160*160*12*8 | H16: 0.944 | I16: 1 | J16: 1510 | K16: 1510 | L16: 0 | M16: =H16*K16/1000 -> 1.42544 | N16: =ROUND(M16*I16-I16*L16,1) -> 1.4
B17: 11 | C17: S38-05 | G17: UC160*160*12*8 | H17: 0.944 | I17: 1 | J17: 1743 | K17: 1658 | L17: 0 | M17: =H17*K17/1000 -> 1.565152 | N17: =ROUND(M17*I17-I17*L17,1) -> 1.6
B18: 12 | C18: S34-03 | G18: UC160*160*12*8 | H18: 0.944 | I18: 1 | J18: 1510 | K18: 1510 | L18: 0 | M18: =ROUNDUP(H18*K18/1000,2) -> 1.43 | N18: =M18*I18-L18*I18 -> 1.43
B19: 13 | C19: SUPPORT GRATING | G19: UC165*305*12*8 | H19: 1.254 | I19: 5 | J19: 5460 | K19: 5460 | L19: 0 | M19: =ROUNDUP(H19*K19/1000,2) -> 6.85 | N19: =M19*I19-L19*I19 -> 34.25
B20: 14 | C20: S-39-06-L | G20: UC200*210*12*10 | H20: 1.22 | I20: 2 | J20: 7829 | K20: 7829 | L20: 0 | M20: =H20*K20/1000 -> 9.55138 | N20: =ROUND(M20*I20-I20*L20,1) -> 19.1
B21: 15 | C21: S-40-06-L | G21: UC200*210*12*10 | H21: 1.22 | I21: 1 | J21: 7829 | K21: 7829 | L21: 0 | M21: =H21*K21/1000 -> 9.55138 | N21: =ROUND(M21*I21-I21*L21,1) -> 9.6
B22: 16 | C22: S-39-04-U | G22: UC200*210*12*10 | H22: 1.22 | I22: 1 | J22: 7579 | K22: 7579 | L22: 0 | M22: =H22*K22/1000 -> 9.24638 | N22: =ROUND(M22*I22-I22*L22,1) -> 9.2
B23: 17 | C23: S-38-06-L | G23: UC200*210*12*10 | H23: 1.22 | I23: 1 | J23: 7829 | K23: 7829 | L23: 0 | M23: =H23*K23/1000 -> 9.55138 | N23: =ROUND(M23*I23-I23*L23,1) -> 9.6
B24: 18 | C24: S-38-06-U | G24: UC200*210*12*10 | H24: 1.22 | I24: 1 | J24: 7829 | K24: 7829 | L24: 0 | M24: =H24*K24/1000 -> 9.55138 | N24: =ROUND(M24*I24-I24*L24,1) -> 9.6
B25: 19 | C25: S-41-04-U | G25: UC200*210*12*10 | H25: 1.22 | I25: 1 | J25: 7579 | K25: 7579 | L25: 0 | M25: =H25*K25/1000 -> 9.24638 | N25: =ROUND(M25*I25-I25*L25,1) -> 9.2
B26: 20 | C26: S-41-02-U | G26: UC200*210*12*10 | H26: 1.22 | I26: 1 | J26: 6732 | K26: 6732 | L26: 0 | M26: =H26*K26/1000 -> 8.21304 | N26: =ROUND(M26*I26-I26*L26,1) -> 8.2
B27: 21 | C27: S-36-05-L | G27: UC200*210*12*10 | H27: 1.22 | I27: 1 | J27: 5486 | K27: 5486 | L27: 0 | M27: =ROUNDUP(H27*K27/1000,2) -> 6.7 | N27: =M27*I27-L27*I27 -> 6.7
B28: 22 | C28: S-36-07-L | G28: UC200*210*12*10 | H28: 1.22 | I28: 1 | J28: 7869 | K28: 7869 | L28: 0 | M28: =H28*K28/1000 -> 9.60018 | N28: =ROUND(M28*I28-I28*L28,1) -> 9.6
B29: 23 | C29: S-39-04-L | G29: UC200*210*12*10 | H29: 1.22 | I29: 1 | J29: 7579 | K29: 7579 | L29: 0 | M29: =H29*K29/1000 -> 9.24638 | N29: =ROUND(M29*I29-I29*L29,1) -> 9.2
B30: 24 | C30: S-38-07-U | G30: UC200*210*12*10 | H30: 1.22 | I30: 1 | J30: 7619 | K30: 7619 | L30: 0 | M30: =H30*K30/1000 -> 9.29518 | N30: =ROUND(M30*I30-I30*L30,1) -> 9.3
B31: 25 | C31: S-41-06-U | G31: UC200*210*12*10 | H31: 1.22 | I31: 2 | J31: 7829 | K31: 7829 | L31: 0 | M31: =ROUNDUP(H31*K31/1000,2) -> 9.56 | N31: =M31*I31-L31*I31 -> 19.12
B32: 26 | C32: S-41-04-L | G32: UC200*210*12*10 | H32: 1.22 | I32: 1 | J32: 7579 | K32: 7579 | L32: 0 | M32: =H32*K32/1000 -> 9.24638 | N32: =ROUND(M32*I32-I32*L32,1) -> 9.2
B33: 27 | C33: S-37-07-U | G33: UC200*210*12*10 | H33: 1.22 | I33: 1 | J33: 7619 | K33: 7619 | L33: 0 | M33: =H33*K33/1000 -> 9.29518 | N33: =ROUND(M33*I33-I33*L33,1) -> 9.3
B34: 28 | C34: S41-04 | G34: UC220*210*12*8 | H34: 1.284 | I34: 3 | J34: 1510 | K34: 1510 | L34: 0 | M34: =H34*K34/1000 -> 1.93884 | N34: =ROUND(M34*I34-I34*L34,1) -> 5.8
B35: 29 | C35: S41-07 | G35: UC220*210*12*8 | H35: 1.284 | I35: 2 | J35: 1814 | K35: 1814 | L35: 0 | M35: =H35*K35/1000 -> 2.329176 | N35: =ROUND(M35*I35-I35*L35,1) -> 4.7
B36: 30 | C36: S43-04 | G36: UC220*210*12*8 | H36: 1.284 | I36: 1 | J36: 1510 | K36: 1510 | L36: 0 | M36: =ROUNDUP(H36*K36/1000,2) -> 1.94 | N36: =M36*I36-L36*I36 -> 1.94
B37: 31 | C37: S39-03 | G37: UC160*160*12*8 | H37: 0.944 | I37: 4 | J37: 1510 | K37: 1510 | L37: 0 | M37: =H37*K37/1000 -> 1.42544 | N37: =ROUND(M37*I37-I37*L37,1) -> 5.7
B38: 32 | C38: S37-05 | G38: UC160*160*12*8 | H38: 0.944 | I38: 2 | J38: 1817 | K38: 1735 | L38: 0 | M38: =H38*K38/1000 -> 1.63784 | N38: =ROUND(M38*I38-I38*L38,1) -> 3.3
B39: 33 | C39: S36-05 | G39: UC160*160*12*8 | H39: 0.944 | I39: 1 | J39: 1909 | K39: 1834 | L39: 0 | M39: =H39*K39/1000 -> 1.731296 | N39: =ROUND(M39*I39-I39*L39,1) -> 1.7
B40: 34 | C40: S43-B-05 | G40: UC160*160*12*8 | H40: 0.944 | I40: 1 | J40: 2237 | K40: 2117 | L40: 0 | M40: =H40*K40/1000 -> 1.998448 | N40: =ROUND(M40*I40-I40*L40,1) -> 2
B41: 35 | C41: S42- G′-02 | G41: UC160*155*10*8 | H41: 0.934 | I41: 1 | J41: 2171 | K41: 2060 | L41: 0 | M41: =H41*K41/1000 -> 1.92404 | N41: =ROUND(M41*I41-I41*L41,1) -> 1.9
B42: 36 | C42: S42-F-05 | G42: UC160*160*12*8 | H42: 0.944 | I42: 1 | J42: 2237 | K42: 2117 | L42: 0 | M42: =H42*K42/1000 -> 1.998448 | N42: =ROUND(M42*I42-I42*L42,1) -> 2
...

Sheet PNT-G-127
B1: صورت مجلس | E1: شماره ویرایش مدرک: | H1: تاریخ ویرایش مدرک: | K1: EC-01-F-09
F4: صورتمجلس
B11: نام پروژه: تعمیرات اساسی ضلع جنوبی اسکله شرقی جزیره خارگ ازمحور19الی45 (PC) | F11: شماره صورت PNT-G-127 | J11: تاریخ :1404/07/28
B14: نام پیمانکار: شرکت صنایع فرا ساحل (صف) | F14: شماره قرارداد: 11048-73-38 | J14: تعداد صفحات پيوست: 5 صفحه
B17: موضـوع: اضافه بهای اعمال رنگ High Solid GLASS FLAKE EPOXY به وسیله دستگاه رنگ پاش بدون هوا (Airless) به ضخامت 250 میکرون در اسکله ( در صورتی که سطح مورد نظر ، لوله تا 8 اینچ یا مقاطع فولادی تا 200 میلی متر باشد.)
B20: بدینوسیله امضا کنندگان ذیل تایید می نمایند , عملیات اعمال رنگ High Solid GLASS FLAKE EPOXY به وسیله دستگاه رنگ پاش بدون هوا (Airless) به ضخامت 250 میکرون در اسکله بر روی المان های ناحیه حد فاصل محور های 19 الی 45 ضلع جنوبی اسکله شرقی مطابق با ریزمتره پیوست به مساحت 618/6 متر مربع انجام گردید.
B26: ردیف | C26: ردیف فهرست بها | E26: شرح | I26: مقدار | K26: واحد
B28: 21 | C28: 641903122 | E28: اضافه بهای اعمال رنگ High Solid GLASS FLAKE EPOXY به وسیله دستگاه رنگ پاش بدون هوا (Airless) به ضخامت 250 میکرون در اسکله ( در صورتی که سطح مورد نظر ، لوله تا 8 اینچ یا مقاطع فولادی تا 200 میلی متر باشد.) | I28: 618/6 | K28: متر مربع
B31: پیمانکار | F31: دستگاه نظارت | J31: کار فرما
B35: منبع مدرک: کارفرما ناظر مقیم پروژه امور قرارداد ها بایگانی دستگاه نظارت پیمانکار

Sheet  المان PNT-G-127
G2: شماره صورتمجلس PNT-G-127
B4: موضـوع: اضافه بهای اعمال رنگ High Solid GLASS FLAKE Epoxy به وسیله دستگاه رنگ پاش بدون هوا (Airless) به ضخامت 250 میکرون در اسکله ( در صورتی که سطح مورد نظر ، لوله تا 8 اینچ یا مقاطع فولادی تا 200 میلی متر باشد.)
B5: موقعیت: محورهای 19 الی 45
B6: ردیف | C6: شرح | H6: سطح واحد(m2) | I6: تعداد | J6: طول/ابعاد (mm) | K6: طول/ابعاد موثر (mm) | L6: همپوشانی یک المان (m2) | M6: سطح یک المان(m2) | N6: سطح کل(m2)
B7: 1 | C7: S36-02 | G7: UC160*160*12*8 | H7: 0.944 | I7: 5 | J7: 2383 | K7: 2238 | L7: 0 | M7: =H7*K7/1000 -> 2.112672 | N7: =ROUND(M7*I7-I7*L7,1) -> 10.6 | AC7: REPORT 116 - FINISH COAT
B8: 2 | C8: S42-03 | G8: UC160*160*12*8 | H8: 0.944 | I8: 3 | J8: 1510 | K8: 1510 | L8: 0 | M8: =H8*K8/1000 -> 1.42544 | N8: =ROUND(M8*I8-I8*L8,1) -> 4.3 | AC8: REPORT 117 - FINISH COAT
B9: 3 | C9: S39-05 | G9: UC160*160*12*8 | H9: 0.944 | I9: 1 | J9: 1817 | K9: 1735 | L9: 0 | M9: =ROUNDUP(H9*K9/1000,2) -> 1.64 | N9: =M9*I9-L9*I9 -> 1.64 | AC9: REPORT 118 - FINISH COAT
B10: 4 | C10: S38-02 | G10: UC160*160*12*8 | H10: 0.944 | I10: 5 | J10: 2402 | K10: 2251 | L10: 0 | M10: =H10*K10/1000 -> 2.124944 | N10: =ROUND(M10*I10-I10*L10,1) -> 10.6
B11: 5 | C11: S35-02 | G11: UC160*160*12*8 | H11: 0.944 | I11: 1 | J11: 2383 | K11: 2238 | L11: 0 | M11: =H11*K11/1000 -> 2.112672 | N11: =ROUND(M11*I11-I11*L11,1) -> 2.1
B12: 6 | C12: S34-02 | G12: UC160*160*12*8 | H12: 0.944 | I12: 1 | J12: 2402 | K12: 2251 | L12: 0 | M12: =H12*K12/1000 -> 2.124944 | N12: =ROUND(M12*I12-I12*L12,1) -> 2.1
B13: 7 | C13: S41-03 | G13: UC160*160*12*8 | H13: 0.944 | I13: 2 | J13: 1510 | K13: 1510 | L13: 0 | M13: =H13*K13/1000 -> 1.42544 | N13: =ROUND(M13*I13-I13*L13,1) -> 2.9
B14: 8 | C14: S35-05 | G14: UC160*160*12*8 | H14: 0.944 | I14: 1 | J14: 1817 | K14: 1735 | L14: 0 | M14: =H14*K14/1000 -> 1.63784 | N14: =ROUND(M14*I14-I14*L14,1) -> 1.6
B15: 9 | C15: S45-02A | G15: UC220*210*12*8 | H15: 1.284 | I15: 0 | J15: 2446 | K15: 2229 | L15: 0 | M15: =H15*K15/1000 -> 2.862036 | N15: =ROUND(M15*I15-I15*L15,1) -> 0
B16: 10 | C16: S36-03 | G16: UC160*160*12*8 | H16: 0.944 | I16: 1 | J16: 1510 | K16: 1510 | L16: 0 | M16: =H16*K16/1000 -> 1.42544 | N16: =ROUND(M16*I16-I16*L16,1) -> 1.4
B17: 11 | C17: S38-05 | G17: UC160*160*12*8 | H17: 0.944 | I17: 1 | J17: 1743 | K17: 1658 | L17: 0 | M17: =H17*K17/1000 -> 1.565152 | N17: =ROUND(M17*I17-I17*L17,1) -> 1.6
B18: 12 | C18: S34-03 | G18: UC160*160*12*8 | H18: 0.944 | I18: 1 | J18: 1510 | K18: 1510 | L18: 0 | M18: =ROUNDUP(H18*K18/1000,2) -> 1.43 | N18: =M18*I18-L18*I18 -> 1.43
B19: 13 | C19: SUPPORT GRATING | G19: UC165*305*12*8 | H19: 1.254 | I19: 5 | J19: 5460 | K19: 5460 | L19: 0 | M19: =ROUNDUP(H19*K19/1000,2) -> 6.85 | N19: =M19*I19-L19*I19 -> 34.25
B20: 14 | C20: S-39-06-L | G20: UC200*210*12*10 | H20: 1.22 | I20: 2 | J20: 7829 | K20: 7829 | L20: 0 | M20: =H20*K20/1000 -> 9.55138 | N20: =ROUND(M20*I20-I20*L20,1) -> 19.1
B21: 15 | C21: S-40-06-L | G21: UC200*210*12*10 | H21: 1.22 | I21: 1 | J21: 7829 | K21: 7829 | L21: 0 | M21: =H21*K21/1000 -> 9.55138 | N21: =ROUND(M21*I21-I21*L21,1) -> 9.6
B22: 16 | C22: S-39-04-U | G22: UC200*210*12*10 | H22: 1.22 | I22: 1 | J22: 7579 | K22: 7579 | L22: 0 | M22: =H22*K22/1000 -> 9.24638 | N22: =ROUND(M22*I22-I22*L22,1) -> 9.2
B23: 17 | C23: S-38-06-L | G23: UC200*210*12*10 | H23: 1.22 | I23: 1 | J23: 7829 | K23: 7829 | L23: 0 | M23: =H23*K23/1000 -> 9.55138 | N23: =ROUND(M23*I23-I23*L23,1) -> 9.6
B24: 18 | C24: S-38-06-U | G24: UC200*210*12*10 | H24: 1.22 | I24: 1 | J24: 7829 | K24: 7829 | L24: 0 | M24: =H24*K24/1000 -> 9.55138 | N24: =ROUND(M24*I24-I24*L24,1) -> 9.6
B25: 19 | C25: S-41-04-U | G25: UC200*210*12*10 | H25: 1.22 | I25: 1 | J25: 7579 | K25: 7579 | L25: 0 | M25: =H25*K25/1000 -> 9.24638 | N25: =ROUND(M25*I25-I25*L25,1) -> 9.2
B26: 20 | C26: S-41-02-U | G26: UC200*210*12*10 | H26: 1.22 | I26: 1 | J26: 6732 | K26: 6732 | L26: 0 | M26: =H26*K26/1000 -> 8.21304 | N26: =ROUND(M26*I26-I26*L26,1) -> 8.2
B27: 21 | C27: S-36-05-L | G27: UC200*210*12*10 | H27: 1.22 | I27: 1 | J27: 5486 | K27: 5486 | L27: 0 | M27: =ROUNDUP(H27*K27/1000,2) -> 6.7 | N27: =M27*I27-L27*I27 -> 6.7
B28: 22 | C28: S-36-07-L | G28: UC200*210*12*10 | H28: 1.22 | I28: 1 | J28: 7869 | K28: 7869 | L28: 0 | M28: =H28*K28/1000 -> 9.60018 | N28: =ROUND(M28*I28-I28*L28,1) -> 9.6
B29: 23 | C29: S-39-04-L | G29: UC200*210*12*10 | H29: 1.22 | I29: 1 | J29: 7579 | K29: 7579 | L29: 0 | M29: =H29*K29/1000 -> 9.24638 | N29: =ROUND(M29*I29-I29*L29,1) -> 9.2
B30: 24 | C30: S-38-07-U | G30: UC200*210*12*10 | H30: 1.22 | I30: 1 | J30: 7619 | K30: 7619 | L30: 0 | M30: =H30*K30/1000 -> 9.29518 | N30: =ROUND(M30*I30-I30*L30,1) -> 9.3
B31: 25 | C31: S-41-06-U | G31: UC200*210*12*10 | H31: 1.22 | I31: 2 | J31: 7829 | K31: 7829 | L31: 0 | M31: =ROUNDUP(H31*K31/1000,2) -> 9.56 | N31: =M31*I31-L31*I31 -> 19.12
B32: 26 | C32: S-41-04-L | G32: UC200*210*12*10 | H32: 1.22 | I32: 1 | J32: 7579 | K32: 7579 | L32: 0 | M32: =H32*K32/1000 -> 9.24638 | N32: =ROUND(M32*I32-I32*L32,1) -> 9.2
B33: 27 | C33: S-37-07-U | G33: UC200*210*12*10 | H33: 1.22 | I33: 1 | J33: 7619 | K33: 7619 | L33: 0 | M33: =H33*K33/1000 -> 9.29518 | N33: =ROUND(M33*I33-I33*L33,1) -> 9.3
B34: 28 | C34: S41-04 | G34: UC220*210*12*8 | H34: 1.284 | I34: 0 | J34: 1510 | K34: 1510 | L34: 0 | M34: =H34*K34/1000 -> 1.93884 | N34: =ROUND(M34*I34-I34*L34,1) -> 0
B35: 29 | C35: S41-07 | G35: UC220*210*12*8 | H35: 1.284 | I35: 0 | J35: 1814 | K35: 1814 | L35: 0 | M35: =H35*K35/1000 -> 2.329176 | N35: =ROUND(M35*I35-I35*L35,1) -> 0
B36: 30 | C36: S43-04 | G36: UC220*210*12*8 | H36: 1.284 | I36: 0 | J36: 1510 | K36: 1510 | L36: 0 | M36: =ROUNDUP(H36*K36/1000,2) -> 1.94 | N36: =M36*I36-L36*I36 -> 0
B37: 31 | C37: S39-03 | G37: UC160*160*12*8 | H37: 0.944 | I37: 4 | J37: 1510 | K37: 1510 | L37: 0 | M37: =H37*K37/1000 -> 1.42544 | N37: =ROUND(M37*I37-I37*L37,1) -> 5.7
B38: 32 | C38: S37-05 | G38: UC160*160*12*8 | H38: 0.944 | I38: 2 | J38: 1817 | K38: 1735 | L38: 0 | M38: =H38*K38/1000 -> 1.63784 | N38: =ROUND(M38*I38-I38*L38,1) -> 3.3
B39: 33 | C39: S36-05 | G39: UC160*160*12*8 | H39: 0.944 | I39: 1 | J39: 1909 | K39: 1834 | L39: 0 | M39: =H39*K39/1000 -> 1.731296 | N39: =ROUND(M39*I39-I39*L39,1) -> 1.7
B40: 34 | C40: S43-B-05 | G40: UC160*160*12*8 | H40: 0.944 | I40: 1 | J40: 2237 | K40: 2117 | L40: 0 | M40: =H40*K40/1000 -> 1.998448 | N40: =ROUND(M40*I40-I40*L40,1) -> 2
B41: 35 | C41: S42- G′-02 | G41: UC160*155*10*8 | H41: 0.934 | I41: 1 | J41: 2171 | K41: 2060 | L41: 0 | M41: =H41*K41/1000 -> 1.92404 | N41: =ROUND(M41*I41-I41*L41,1) -> 1.9
B42: 36 | C42: S42-F-05 | G42: UC160*160*12*8 | H42: 0.944 | I42: 1 | J42: 2237 | K42: 2117 | L42: 0 | M42: =H42*K42/1000 -> 1.998448 | N42: =ROUND(M42*I42-I42*L42,1) -> 2
...

Sheet PNT-G-126
B1: صورت مجلس | E1: شماره ویرایش مدرک: | H1: تاریخ ویرایش مدرک: | K1: EC-01-F-09
F4: صورتمجلس
B11: نام پروژه: تعمیرات اساسی ضلع جنوبی اسکله شرقی جزیره خارگ ازمحور19الی45 (PC) | F11: شماره صورت PNT-G-126 | J11: تاریخ :1404/07/28
B14: نام پیمانکار: شرکت صنایع فرا ساحل (صف) | F14: شماره قرارداد: 11048-73-38 | J14: تعداد صفحات پيوست: 5 صفحه
B17: موضـوع: اعمال رنگ High Solid GLASS FLAKE EPOXY به وسیله دستگاه رنگ پاش بدون هوا (Airless) به ضخامت 250 میکرون در اسکله
B20: بدینوسیله امضا کنندگان ذیل تایید می نمایند , عملیات اعمال رنگ High Solid GLASS FLAKE EPOXY به وسیله دستگاه رنگ پاش بدون هوا (Airless) به ضخامت 250 میکرون در اسکله بر روی المان های ناحیه حد فاصل محور های 19 الی 45 ضلع جنوبی اسکله شرقی مطابق با ریزمتره پیوست به مساحت 655/0 متر مربع انجام گردید.
B26: ردیف | C26: ردیف فهرست بها | E26: شرح | I26: مقدار | K26: واحد
B28: 17 | C28: 641903107 | E28: اعمال رنگ High Solid GLASS FLAKE EPOXY به وسیله دستگاه رنگ پاش بدون هوا (Airless) به ضخامت 250 میکرون در اسکله | I28: 655/0 | K28: متر مربع
B31: پیمانکار | F31: دستگاه نظارت | J31: کار فرما
B35: منبع مدرک: کارفرما ناظر مقیم پروژه امور قرارداد ها بایگانی دستگاه نظارت پیمانکار

Sheet  المان PNT-G-126
G2: شماره صورتمجلس PNT-G-126
B4: موضـوع: اعمال رنگ High Solid GLASS FLAKE EPOXY به وسیله دستگاه رنگ پاش بدون هوا (Airless) به ضخامت 250 میکرون در اسکله
B5: موقعیت: محورهای 19 الی 45
B6: ردیف | C6: شرح | H6: سطح واحد(m2) | I6: تعداد | J6: طول/ابعاد (mm) | K6: طول/ابعاد موثر (mm) | L6: همپوشانی یک المان (m2) | M6: سطح یک المان(m2) | N6: سطح کل(m2)
B7: 1 | C7: S36-02 | G7: UC160*160*12*8 | H7: 0.944 | I7: 5 | J7: 2383 | K7: 2238 | L7: 0 | M7: =H7*K7/1000 -> 2.112672 | N7: =ROUND(M7*I7-I7*L7,1) -> 10.6 | AC7: REPORT 116 - FINISH COAT
B8: 2 | C8: S42-03 | G8: UC160*160*12*8 | H8: 0.944 | I8: 3 | J8: 1510 | K8: 1510 | L8: 0 | M8: =H8*K8/1000 -> 1.42544 | N8: =ROUND(M8*I8-I8*L8,1) -> 4.3 | AC8: REPORT 117 - FINISH COAT
B9: 3 | C9: S39-05 | G9: UC160*160*12*8 | H9: 0.944 | I9: 1 | J9: 1817 | K9: 1735 | L9: 0 | M9: =ROUNDUP(H9*K9/1000,2) -> 1.64 | N9: =M9*I9-L9*I9 -> 1.64 | AC9: REPORT 118 - FINISH COAT
B10: 4 | C10: S38-02 | G10: UC160*160*12*8 | H10: 0.944 | I10: 5 | J10: 2402 | K10: 2251 | L10: 0 | M10: =H10*K10/1000 -> 2.124944 | N10: =ROUND(M10*I10-I10*L10,1) -> 10.6
B11: 5 | C11: S35-02 | G11: UC160*160*12*8 | H11: 0.944 | I11: 1 | J11: 2383 | K11: 2238 | L11: 0 | M11: =H11*K11/1000 -> 2.112672 | N11: =ROUND(M11*I11-I11*L11,1) -> 2.1
B12: 6 | C12: S34-02 | G12: UC160*160*12*8 | H12: 0.944 | I12: 1 | J12: 2402 | K12: 2251 | L12: 0 | M12: =H12*K12/1000 -> 2.124944 | N12: =ROUND(M12*I12-I12*L12,1) -> 2.1
B13: 7 | C13: S41-03 | G13: UC160*160*12*8 | H13: 0.944 | I13: 2 | J13: 1510 | K13: 1510 | L13: 0 | M13: =H13*K13/1000 -> 1.42544 | N13: =ROUND(M13*I13-I13*L13,1) -> 2.9
B14: 8 | C14: S35-05 | G14: UC160*160*12*8 | H14: 0.944 | I14: 1 | J14: 1817 | K14: 1735 | L14: 0 | M14: =H14*K14/1000 -> 1.63784 | N14: =ROUND(M14*I14-I14*L14,1) -> 1.6
B15: 9 | C15: S45-02A | G15: UC220*210*12*8 | H15: 1.284 | I15: 1 | J15: 2446 | K15: 2229 | L15: 0 | M15: =H15*K15/1000 -> 2.862036 | N15: =ROUND(M15*I15-I15*L15,1) -> 2.9
B16: 10 | C16: S36-03 | G16: UC160*160*12*8 | H16: 0.944 | I16: 1 | J16: 1510 | K16: 1510 | L16: 0 | M16: =H16*K16/1000 -> 1.42544 | N16: =ROUND(M16*I16-I16*L16,1) -> 1.4
B17: 11 | C17: S38-05 | G17: UC160*160*12*8 | H17: 0.944 | I17: 1 | J17: 1743 | K17: 1658 | L17: 0 | M17: =H17*K17/1000 -> 1.565152 | N17: =ROUND(M17*I17-I17*L17,1) -> 1.6
B18: 12 | C18: S34-03 | G18: UC160*160*12*8 | H18: 0.944 | I18: 1 | J18: 1510 | K18: 1510 | L18: 0 | M18: =ROUNDUP(H18*K18/1000,2) -> 1.43 | N18: =M18*I18-L18*I18 -> 1.43
B19: 13 | C19: SUPPORT GRATING | G19: UC165*305*12*8 | H19: 1.254 | I19: 5 | J19: 5460 | K19: 5460 | L19: 0 | M19: =ROUNDUP(H19*K19/1000,2) -> 6.85 | N19: =M19*I19-L19*I19 -> 34.25
B20: 14 | C20: S-39-06-L | G20: UC200*210*12*10 | H20: 1.22 | I20: 2 | J20: 7829 | K20: 7829 | L20: 0 | M20: =H20*K20/1000 -> 9.55138 | N20: =ROUND(M20*I20-I20*L20,1) -> 19.1
B21: 15 | C21: S-40-06-L | G21: UC200*210*12*10 | H21: 1.22 | I21: 1 | J21: 7829 | K21: 7829 | L21: 0 | M21: =H21*K21/1000 -> 9.55138 | N21: =ROUND(M21*I21-I21*L21,1) -> 9.6
B22: 16 | C22: S-39-04-U | G22: UC200*210*12*10 | H22: 1.22 | I22: 1 | J22: 7579 | K22: 7579 | L22: 0 | M22: =H22*K22/1000 -> 9.24638 | N22: =ROUND(M22*I22-I22*L22,1) -> 9.2
B23: 17 | C23: S-38-06-L | G23: UC200*210*12*10 | H23: 1.22 | I23: 1 | J23: 7829 | K23: 7829 | L23: 0 | M23: =H23*K23/1000 -> 9.55138 | N23: =ROUND(M23*I23-I23*L23,1) -> 9.6
B24: 18 | C24: S-38-06-U | G24: UC200*210*12*10 | H24: 1.22 | I24: 1 | J24: 7829 | K24: 7829 | L24: 0 | M24: =H24*K24/1000 -> 9.55138 | N24: =ROUND(M24*I24-I24*L24,1) -> 9.6
B25: 19 | C25: S-41-04-U | G25: UC200*210*12*10 | H25: 1.22 | I25: 1 | J25: 7579 | K25: 7579 | L25: 0 | M25: =H25*K25/1000 -> 9.24638 | N25: =ROUND(M25*I25-I25*L25,1) -> 9.2
B26: 20 | C26: S-41-02-U | G26: UC200*210*12*10 | H26: 1.22 | I26: 1 | J26: 6732 | K26: 6732 | L26: 0 | M26: =H26*K26/1000 -> 8.21304 | N26: =ROUND(M26*I26-I26*L26,1) -> 8.2
B27: 21 | C27: S-36-05-L | G27: UC200*210*12*10 | H27: 1.22 | I27: 1 | J27: 5486 | K27: 5486 | L27: 0 | M27: =ROUNDUP(H27*K27/1000,2) -> 6.7 | N27: =M27*I27-L27*I27 -> 6.7
B28: 22 | C28: S-36-07-L | G28: UC200*210*12*10 | H28: 1.22 | I28: 1 | J28: 7869 | K28: 7869 | L28: 0 | M28: =H28*K28/1000 -> 9.60018 | N28: =ROUND(M28*I28-I28*L28,1) -> 9.6
B29: 23 | C29: S-39-04-L | G29: UC200*210*12*10 | H29: 1.22 | I29: 1 | J29: 7579 | K29: 7579 | L29: 0 | M29: =H29*K29/1000 -> 9.24638 | N29: =ROUND(M29*I29-I29*L29,1) -> 9.2
B30: 24 | C30: S-38-07-U | G30: UC200*210*12*10 | H30: 1.22 | I30: 1 | J30: 7619 | K30: 7619 | L30: 0 | M30: =H30*K30/1000 -> 9.29518 | N30: =ROUND(M30*I30-I30*L30,1) -> 9.3
B31: 25 | C31: S-41-06-U | G31: UC200*210*12*10 | H31: 1.22 | I31: 2 | J31: 7829 | K31: 7829 | L31: 0 | M31: =ROUNDUP(H31*K31/1000,2) -> 9.56 | N31: =M31*I31-L31*I31 -> 19.12
B32: 26 | C32: S-41-04-L | G32: UC200*210*12*10 | H32: 1.22 | I32: 1 | J32: 7579 | K32: 7579 | L32: 0 | M32: =H32*K32/1000 -> 9.24638 | N32: =ROUND(M32*I32-I32*L32,1) -> 9.2
B33: 27 | C33: S-37-07-U | G33: UC200*210*12*10 | H33: 1.22 | I33: 1 | J33: 7619 | K33: 7619 | L33: 0 | M33: =H33*K33/1000 -> 9.29518 | N33: =ROUND(M33*I33-I33*L33,1) -> 9.3
B34: 28 | C34: S41-04 | G34: UC220*210*12*8 | H34: 1.284 | I34: 3 | J34: 1510 | K34: 1510 | L34: 0 | M34: =H34*K34/1000 -> 1.93884 | N34: =ROUND(M34*I34-I34*L34,1) -> 5.8
B35: 29 | C35: S41-07 | G35: UC220*210*12*8 | H35: 1.284 | I35: 2 | J35: 1814 | K35: 1814 | L35: 0 | M35: =H35*K35/1000 -> 2.329176 | N35: =ROUND(M35*I35-I35*L35,1) -> 4.7
B36: 30 | C36: S43-04 | G36: UC220*210*12*8 | H36: 1.284 | I36: 1 | J36: 1510 | K36: 1510 | L36: 0 | M36: =ROUNDUP(H36*K36/1000,2) -> 1.94 | N36: =M36*I36-L36*I36 -> 1.94
B37: 31 | C37: S39-03 | G37: UC160*160*12*8 | H37: 0.944 | I37: 4 | J37: 1510 | K37: 1510 | L37: 0 | M37: =H37*K37/1000 -> 1.42544 | N37: =ROUND(M37*I37-I37*L37,1) -> 5.7
B38: 32 | C38: S37-05 | G38: UC160*160*12*8 | H38: 0.944 | I38: 2 | J38: 1817 | K38: 1735 | L38: 0 | M38: =H38*K38/1000 -> 1.63784 | N38: =ROUND(M38*I38-I38*L38,1) -> 3.3
B39: 33 | C39: S36-05 | G39: UC160*160*12*8 | H39: 0.944 | I39: 1 | J39: 1909 | K39: 1834 | L39: 0 | M39: =H39*K39/1000 -> 1.731296 | N39: =ROUND(M39*I39-I39*L39,1) -> 1.7
B40: 34 | C40: S43-B-05 | G40: UC160*160*12*8 | H40: 0.944 | I40: 1 | J40: 2237 | K40: 2117 | L40: 0 | M40: =H40*K40/1000 -> 1.998448 | N40: =ROUND(M40*I40-I40*L40,1) -> 2
B41: 35 | C41: S42- G′-02 | G41: UC160*155*10*8 | H41: 0.934 | I41: 1 | J41: 2171 | K41: 2060 | L41: 0 | M41: =H41*K41/1000 -> 1.92404 | N41: =ROUND(M41*I41-I41*L41,1) -> 1.9
B42: 36 | C42: S42-F-05 | G42: UC160*160*12*8 | H42: 0.944 | I42: 1 | J42: 2237 | K42: 2117 | L42: 0 | M42: =H42*K42/1000 -> 1.998448 | N42: =ROUND(M42*I42-I42*L42,1) -> 2
...

Sheet PNT-G-125
B1: صورت مجلس | E1: شماره ویرایش مدرک: | H1: تاریخ ویرایش مدرک: | K1: EC-01-F-09
F4: صورتمجلس
B11: نام پروژه: تعمیرات اساسی ضلع جنوبی اسکله شرقی جزیره خارگ ازمحور19الی45 (PC) | F11: شماره صورتمجلس PNT-G-125 | J11: تاریخ :1404/07/15
B14: نام پیمانکار: شرکت صنایع فرا ساحل (صف) | F14: شماره قرارداد: 11048-73-38 | J14: تعداد صفحات پيوست: 5 صفحه
B17: موضـوع: تهیه رنگ High Solid GLASS FLAKE EPOXY به ضخامت 250 میکرون
B20: بدینوسیله امضا کنندگان ذیل تایید می نمایند , تهیه رنگ High Solid GLASS FLAKE EPOXY به ضخامت 250 میکرون برای المان های ناحیه حد فاصل محور های 19 الی 45 ضلع جنوبی اسکله شرقی مطابق با ریزمتره پیوست به مساحت 184/4 متر مربع انجام گردید.
B26: ردیف | C26: ردیف فهرست بها | E26: شرح | I26: مقدار | K26: واحد
B28: 28 | C28: 641904105 | E28: تهیه رنگ High Solid GLASS FLAKE EPOXY به ضخامت 250 میکرون | I28: 184/4 | K28: متر مربع
B31: پیمانکار | F31: دستگاه نظارت | J31: کار فرما
B35: منبع مدرک: کارفرما ناظر مقیم پروژه امور قرارداد ها بایگانی دستگاه نظارت پیمانکار

Sheet PNT-G-124
B1: صورت مجلس | E1: شماره ویرایش مدرک: | H1: تاریخ ویرایش مدرک: | K1: EC-01-F-09
F4: صورتمجلس
B11: نام پروژه: تعمیرات اساسی ضلع جنوبی اسکله شرقی جزیره خارگ ازمحور19الی45 (PC) | F11: شماره صورت PNT-G-124 | J11: تاریخ :1404/07/15
B14: نام پیمانکار: شرکت صنایع فرا ساحل (صف) | F14: شماره قرارداد: 11048-73-38 | J14: تعداد صفحات پيوست: 4 صفحه
B17: موضـوع: اضافه بها اعمال رنگ High Solid GLASS FLAKE EPOXY به وسیله دستگاه رنگ پاش بدون هوا (Airless) به ضخامت 250 میکرون درناحیه بالای اسپلش زون تا زیر عرشه اسکله معادل 20% بهای واحد ردیف 641903107 طبق بند 13 مقدمه فصل 19 فهرست بها
B20: بدینوسیله امضا کنندگان ذیل تایید می نمایند , عملیات اعمال رنگ High Solid GLASS FLAKE EPOXY به وسیله دستگاه رنگ پاش بدون هوا (Airless) به ضخامت 250 میکرون در درناحیه بالای اسپلش زون تا زیر عرشه اسکله بر روی المان های ناحیه حد فاصل محور های 19 الی 45 ضلع جنوبی اسکله شرقی مطابق با ریزمتره پیوست به مساحت 184/4 متر مربع انجام گردید.
B26: ردیف | C26: ردیف فهرست بها | E26: شرح | I26: مقدار | K26: واحد
B28: 24 | C28: 641903132* | E28: اضافه بها اعمال رنگ High Solid GLASS FLAKE EPOXY به وسیله دستگاه رنگ پاش بدون هوا (Airless) به ضخامت 250 میکرون درناحیه بالای اسپلش زون تا زیر عرشه اسکله معادل 20% بهای واحد ردیف 641903107 طبق بند 13 مقدمه فصل 19 فهرست بها | I28: 184/4 | K28: متر مربع | P28: 569.1511
B31: پیمانکار | F31: دستگاه نظارت | J31: کار فرما
B35: منبع مدرک: کارفرما ناظر مقیم پروژه امور قرارداد ها بایگانی دستگاه نظارت پیمانکار

Sheet  المان PNT-G-124
G2: شماره صورتمجلس PNT-G-124
B5: موضـوع:اضافه بها اعمال رنگ High Solid GLASS FLAKE EPOXY به وسیله دستگاه رنگ پاش بدون هوا (Airless) به ضخامت 250 میکرون درناحیه بالای اسپلش زون تا زیر عرشه اسکله معادل 20% بهای واحد ردیف 641903107 طبق بند 13 مقدمه فصل 19 فهرست بها
B6: موقعیت: محورهای 19 الی 45
B7: 1 | C7: S-24-07-U | G7: UC200*210*12*10 | H7: 1.22 | I7: 1 | J7: 3659 | K7: 3569 | L7: =0.126+0.114 -> 0.24 | M7: =H7*K7/1000 -> 4.35418 | N7: =ROUND(M7*I7-I7*L7,1) -> 4.1
B8: 2 | C8: S-24-06-U | G8: UC200*210*12*10 | H8: 1.22 | I8: 1 | J8: 3909 | K8: 3847 | L8: =0.126+0.114 -> 0.24 | M8: =H8*K8/1000 -> 4.69334 | N8: =ROUND(M8*I8-I8*L8,1) -> 4.5
B9: 3 | C9: S-24-02-U | G9: UC200*210*12*10 | H9: 1.22 | I9: 1 | J9: 7829 | K9: 7829 | L9: =0.252+0.1088 -> 0.3608 | M9: =H9*K9/1000 -> 9.55138 | N9: =ROUND(M9*I9-I9*L9,1) -> 9.2
B10: 4 | C10: S-24-07-L | G10: UC200*210*12*10 | H10: 1.22 | I10: 1 | J10: 3659 | K10: 3569 | L10: =0.126+0.114 -> 0.24 | M10: =H10*K10/1000 -> 4.35418 | N10: =ROUND(M10*I10-I10*L10,1) -> 4.1
B11: 5 | C11: S-24-06-L | G11: UC200*210*12*10 | H11: 1.22 | I11: 1 | J11: 3909 | K11: 3847 | L11: =0.126+0.114 -> 0.24 | M11: =H11*K11/1000 -> 4.69334 | N11: =ROUND(M11*I11-I11*L11,1) -> 4.5
B12: 6 | C12: S-24-02-L | G12: UC200*210*12*10 | H12: 1.22 | I12: 1 | J12: 7829 | K12: 7829 | L12: 0.252 | M12: =H12*K12/1000 -> 9.55138 | N12: =ROUND(M12*I12-I12*L12,1) -> 9.3
B13: 7 | C13: GUSSET - LOWER DECK (Row E) AXIS 25 | G13: TYP.05 (LOWER DECK) | H13: 2.042 | I13: 1 | J13: - | K13: - | L13: =0.85*0.308+6*2*0.3*0.21 -> 1.0178 | M13: =H13*I13 -> 2.042 | N13: =ROUND(M13*I13-I13*L13,1) -> 1
B14: 8 | C14: GUSSET - UPPER DECK (Row E) AXIS 25 | G14: TYP.9 (UPPER DECK) | H14: 1.895172 | I14: 1 | J14: - | K14: - | L14: 0.751525 | M14: =H14*I14 -> 1.895172 | N14: =ROUND(M14*I14-I14*L14,1) -> 1.1 | AK14: REPORT 112 - FINISH COAT
B15: 9 | C15: GUSSET - LOWER DECK (Row E~F) AXIS 24~25 | G15: TYP.12 (LOWER DECK) | H15: 0.835 | I15: 1 | J15: - | K15: - | L15: 0.3368 | M15: =H15*I15 -> 0.835 | N15: =ROUND(M15*I15-I15*L15,1) -> 0.5
B16: 10 | C16: GUSSET - UPPER DECK (Row E~F) AXIS 24~25 | G16: TYP.08 (UPPER DECK) | H16: =H15 -> 0.835 | I16: 1 | J16: - | K16: - | L16: =L15 -> 0.3368 | M16: =H16*I16 -> 0.835 | N16: =ROUND(M16*I16-I16*L16,1) -> 0.5
B17: 11 | C17: S-24-03-U | G17: UC200*210*12*10 | H17: 1.22 | I17: 1 | J17: 5486 | K17: 5486 | L17: 0.126 | M17: =H17*K17/1000 -> 6.69292 | N17: =ROUND(M17*I17-I17*L17,1) -> 6.6
B18: 12 | C18: S-24-03-L | G18: UC200*210*12*10 | H18: 1.22 | I18: 1 | J18: 5486 | K18: 5486 | L18: 0.15834 | M18: =H18*K18/1000 -> 6.69292 | N18: =ROUND(M18*I18-I18*L18,1) -> 6.5
B19: 13 | C19: S24-E-03 | G19: UC160*160*12*8 | H19: 0.944 | I19: 2 | J19: 2948 | K19: 2771 | L19: 0 | M19: =ROUNDUP(H19*K19/1000,1) -> 2.7 | N19: =M19*I19-L19*I19 -> 5.4
B20: 14 | C20: S24-E-04 | G20: UC160*160*12*8 | H20: 0.944 | I20: 1 | J20: 1629 | K20: 1629 | L20: 0 | M20: =ROUNDUP(H20*K20/1000,1) -> 1.6 | N20: =M20*I20-L20*I20 -> 1.6
B21: 15 | C21: S25-08 | G21: UC220*210*12*8 | H21: 1.284 | I21: 1 | J21: 1510 | K21: 1510 | L21: 0 | M21: =H21*K21/1000 -> 1.93884 | N21: =ROUND(M21*I21-I21*L21,1) -> 1.9
B22: 16 | C22: S25-03 | G22: UC160*160*12*8 | H22: 0.944 | I22: 3 | J22: 1510 | K22: 1510 | L22: 0 | M22: =H22*K22/1000 -> 1.42544 | N22: =ROUND(M22*I22-I22*L22,1) -> 4.3
B23: 17 | C23: S25-02 | G23: UC160*160*12*8 | H23: 0.944 | I23: 2 | J23: 2402 | K23: 2251 | L23: 0 | M23: =H23*K23/1000 -> 2.124944 | N23: =ROUND(M23*I23-I23*L23,1) -> 4.2
B24: 18 | C24: S25-04 | G24: UC160*160*12*8 | H24: 0.944 | I24: 1 | J24: 1817 | K24: 1735 | L24: 0 | M24: =H24*K24/1000 -> 1.63784 | N24: =ROUND(M24*I24-I24*L24,1) -> 1.6
B25: 19 | C25: S19-45(lower) AXIS 25 ROW E~F | G25: UC313*308*20*15 | H25: 1.828 | I25: 1 | J25: 5181 | K25: 5181 | L25: =0.5*0.85*0.308+0.5*1.9*0.308 -> 0.4235 | M25: =K25*H25/1000 -> 9.470868 | N25: =ROUND(M25*I25-I25*L25,1) -> 9
B26: 20 | C26: S19-45 (upper) AXIS 25 ROW E~F | G26: UC313*308*20*15 | H26: 1.828 | I26: 1 | J26: 5181 | K26: 5181 | L26: =0.5*0.85*0.308 -> 0.1309 | M26: =K26*H26/1000 -> 9.470868 | N26: =ROUND(M26*I26-I26*L26,1) -> 9.3
B27: 21 | C27: BOX TO PILE (AXIS-25 ROW E) | G27: 1920*720 | H27: 3.58 | I27: 1 | J27: - | K27: - | L27: =1.9*0.308 -> 0.5852 | M27: =H27 -> 3.58 | N27: =ROUND(M27*I27-L27*I27,1) -> 3
B28: جمع کل | N28: =SUM(N7:N27) -> 92.2
B29: جمع کل دو لایه | N29: =N28*2 -> 184.4
B30: پیمانکار : تاریخ : | I30: دستگاه نظارت : تاریخ :
B32: منبع مدرک: کارفرما ناظر مقیم پروژه امور قرارداد ها بایگانی دستگاه نظارت پیمانکار

Sheet PNT-G-123
B1: صورت مجلس | E1: شماره ویرایش مدرک: | H1: تاریخ ویرایش مدرک: | K1: EC-01-F-09
F4: صورتمجلس
B11: نام پروژه: تعمیرات اساسی ضلع جنوبی اسکله شرقی جزیره خارگ ازمحور19الی45 (PC) | F11: شماره صورت PNT-G-123 | J11: تاریخ :1404/07/15
B14: نام پیمانکار: شرکت صنایع فرا ساحل (صف) | F14: شماره قرارداد: 11048-73-38 | J14: تعداد صفحات پيوست: 4 صفحه
B17: موضـوع: اضافه بهای اعمال رنگ High Solid GLASS FLAKE EPOXY به وسیله دستگاه رنگ پاش بدون هوا (Airless) به ضخامت 250 میکرون در اسکله ( در صورتی که سطح مورد نظر ، لوله تا 8 اینچ یا مقاطع فولادی تا 200 میلی متر باشد.)
B20: بدینوسیله امضا کنندگان ذیل تایید می نمایند , عملیات اعمال رنگ High Solid GLASS FLAKE EPOXY به وسیله دستگاه رنگ پاش بدون هوا (Airless) به ضخامت 250 میکرون در اسکله بر روی المان های ناحیه حد فاصل محور های 19 الی 45 ضلع جنوبی اسکله شرقی مطابق با ریزمتره پیوست به مساحت 131/8 متر مربع انجام گردید.
B26: ردیف | C26: ردیف فهرست بها | E26: شرح | I26: مقدار | K26: واحد
B28: 21 | C28: 641903122 | E28: اضافه بهای اعمال رنگ High Solid GLASS FLAKE EPOXY به وسیله دستگاه رنگ پاش بدون هوا (Airless) به ضخامت 250 میکرون در اسکله ( در صورتی که سطح مورد نظر ، لوله تا 8 اینچ یا مقاطع فولادی تا 200 میلی متر باشد.) | I28: 131/8 | K28: متر مربع
B31: پیمانکار | F31: دستگاه نظارت | J31: کار فرما
B35: منبع مدرک: کارفرما ناظر مقیم پروژه امور قرارداد ها بایگانی دستگاه نظارت پیمانکار

Sheet  المان PNT-G-123
G2: شماره صورتمجلس PNT-PG123
B5: موضـوع: اضافه بهای اعمال رنگ High Solid GLASS FLAKE Epoxy به وسیله دستگاه رنگ پاش بدون هوا (Airless) به ضخامت 250 میکرون در اسکله ( در صورتی که سطح مورد نظر ، لوله تا 8 اینچ یا مقاطع فولادی تا 200 میلی متر باشد.)
B6: موقعیت: محورهای 19 الی 45
B7: 1 | C7: S-24-07-U | G7: UC200*210*12*10 | H7: 1.22 | I7: 1 | J7: 3659 | K7: 3569 | L7: =0.126+0.114 -> 0.24 | M7: =H7*K7/1000 -> 4.35418 | N7: =ROUND(M7*I7-I7*L7,1) -> 4.1
B8: 2 | C8: S-24-06-U | G8: UC200*210*12*10 | H8: 1.22 | I8: 1 | J8: 3909 | K8: 3847 | L8: =0.126+0.114 -> 0.24 | M8: =H8*K8/1000 -> 4.69334 | N8: =ROUND(M8*I8-I8*L8,1) -> 4.5
B9: 3 | C9: S-24-02-U | G9: UC200*210*12*10 | H9: 1.22 | I9: 1 | J9: 7829 | K9: 7829 | L9: =0.252+0.1088 -> 0.3608 | M9: =H9*K9/1000 -> 9.55138 | N9: =ROUND(M9*I9-I9*L9,1) -> 9.2
B10: 4 | C10: S-24-07-L | G10: UC200*210*12*10 | H10: 1.22 | I10: 1 | J10: 3659 | K10: 3569 | L10: =0.126+0.114 -> 0.24 | M10: =H10*K10/1000 -> 4.35418 | N10: =ROUND(M10*I10-I10*L10,1) -> 4.1
B11: 5 | C11: S-24-06-L | G11: UC200*210*12*10 | H11: 1.22 | I11: 1 | J11: 3909 | K11: 3847 | L11: =0.126+0.114 -> 0.24 | M11: =H11*K11/1000 -> 4.69334 | N11: =ROUND(M11*I11-I11*L11,1) -> 4.5
B12: 6 | C12: S-24-02-L | G12: UC200*210*12*10 | H12: 1.22 | I12: 1 | J12: 7829 | K12: 7829 | L12: 0.252 | M12: =H12*K12/1000 -> 9.55138 | N12: =ROUND(M12*I12-I12*L12,1) -> 9.3
B13: 7 | C13: GUSSET - LOWER DECK (Row E) AXIS 25 | G13: TYP.05 (LOWER DECK) | H13: 2.042 | I13: 0 | J13: - | K13: - | L13: =0.85*0.308+6*2*0.3*0.21 -> 1.0178 | M13: =H13*I13 -> 0 | N13: =ROUND(M13*I13-I13*L13,1) -> 0
B14: 8 | C14: GUSSET - UPPER DECK (Row E) AXIS 25 | G14: TYP.9 (UPPER DECK) | H14: 1.895172 | I14: 0 | J14: - | K14: - | L14: 0.751525 | M14: =H14*I14 -> 0 | N14: =ROUND(M14*I14-I14*L14,1) -> 0 | AK14: REPORT 112 - FINISH COAT
B15: 9 | C15: GUSSET - LOWER DECK (Row E~F) AXIS 24~25 | G15: TYP.12 (LOWER DECK) | H15: 0.835 | I15: 0 | J15: - | K15: - | L15: 0.3368 | M15: =H15*I15 -> 0 | N15: =ROUND(M15*I15-I15*L15,1) -> 0
B16: 10 | C16: GUSSET - UPPER DECK (Row E~F) AXIS 24~25 | G16: TYP.08 (UPPER DECK) | H16: =H15 -> 0.835 | I16: 0 | J16: - | K16: - | L16: =L15 -> 0.3368 | M16: =H16*I16 -> 0 | N16: =ROUND(M16*I16-I16*L16,1) -> 0
B17: 11 | C17: S-24-03-U | G17: UC200*210*12*10 | H17: 1.22 | I17: 1 | J17: 5486 | K17: 5486 | L17: 0.126 | M17: =H17*K17/1000 -> 6.69292 | N17: =ROUND(M17*I17-I17*L17,1) -> 6.6
B18: 12 | C18: S-24-03-L | G18: UC200*210*12*10 | H18: 1.22 | I18: 1 | J18: 5486 | K18: 5486 | L18: 0.15834 | M18: =H18*K18/1000 -> 6.69292 | N18: =ROUND(M18*I18-I18*L18,1) -> 6.5
B19: 13 | C19: S24-E-03 | G19: UC160*160*12*8 | H19: 0.944 | I19: 2 | J19: 2948 | K19: 2771 | L19: 0 | M19: =ROUNDUP(H19*K19/1000,1) -> 2.7 | N19: =M19*I19-L19*I19 -> 5.4
B20: 14 | C20: S24-E-04 | G20: UC160*160*12*8 | H20: 0.944 | I20: 1 | J20: 1629 | K20: 1629 | L20: 0 | M20: =ROUNDUP(H20*K20/1000,1) -> 1.6 | N20: =M20*I20-L20*I20 -> 1.6
B21: 15 | C21: S25-08 | G21: UC220*210*12*8 | H21: 1.284 | I21: 0 | J21: 1510 | K21: 1510 | L21: 0 | M21: =H21*K21/1000 -> 1.93884 | N21: =ROUND(M21*I21-I21*L21,1) -> 0
B22: 16 | C22: S25-03 | G22: UC160*160*12*8 | H22: 0.944 | I22: 3 | J22: 1510 | K22: 1510 | L22: 0 | M22: =H22*K22/1000 -> 1.42544 | N22: =ROUND(M22*I22-I22*L22,1) -> 4.3
B23: 17 | C23: S25-02 | G23: UC160*160*12*8 | H23: 0.944 | I23: 2 | J23: 2402 | K23: 2251 | L23: 0 | M23: =H23*K23/1000 -> 2.124944 | N23: =ROUND(M23*I23-I23*L23,1) -> 4.2
B24: 18 | C24: S25-04 | G24: UC160*160*12*8 | H24: 0.944 | I24: 1 | J24: 1817 | K24: 1735 | L24: 0 | M24: =H24*K24/1000 -> 1.63784 | N24: =ROUND(M24*I24-I24*L24,1) -> 1.6
B25: 19 | C25: S19-45(lower) AXIS 25 ROW E~F | G25: UC313*308*20*15 | H25: 1.828 | I25: 0 | J25: 5181 | K25: 5181 | L25: =0.5*0.85*0.308+0.5*1.9*0.308 -> 0.4235 | M25: =K25*H25/1000 -> 9.470868 | N25: =ROUND(M25*I25-I25*L25,1) -> 0
B26: 20 | C26: S19-45 (upper) AXIS 25 ROW E~F | G26: UC313*308*20*15 | H26: 1.828 | I26: 0 | J26: 5181 | K26: 5181 | L26: =0.5*0.85*0.308 -> 0.1309 | M26: =K26*H26/1000 -> 9.470868 | N26: =ROUND(M26*I26-I26*L26,1) -> 0
B27: 21 | C27: BOX TO PILE (AXIS-25 ROW E) | G27: 1920*720 | H27: 3.58 | I27: 0 | J27: - | K27: - | L27: =1.9*0.308 -> 0.5852 | M27: =H27 -> 3.58 | N27: =ROUND(M27*I27-L27*I27,1) -> 0
B28: جمع کل | N28: =SUM(N7:N27) -> 65.9
B29: جمع کل دو لایه | N29: =N28*2 -> 131.8
B30: پیمانکار : تاریخ : | I30: دستگاه نظارت : تاریخ :
B32: منبع مدرک: کارفرما ناظر مقیم پروژه امور قرارداد ها بایگانی دستگاه نظارت پیمانکار

Sheet PNT-G-122
B1: صورت مجلس | E1: شماره ویرایش مدرک: | H1: تاریخ ویرایش مدرک: | K1: EC-01-F-09
F4: صورتمجلس
B11: نام پروژه: تعمیرات اساسی ضلع جنوبی اسکله شرقی جزیره خارگ ازمحور19الی45 (PC) | F11: شماره صورت PNT-G-122 | J11: تاریخ :1404/07/15
B14: نام پیمانکار: شرکت صنایع فرا ساحل (صف) | F14: شماره قرارداد: 11048-73-38 | J14: تعداد صفحات پيوست: 4 صفحه
B17: موضـوع: اعمال رنگ High Solid GLASS FLAKE EPOXY به وسیله دستگاه رنگ پاش بدون هوا (Airless) به ضخامت 250 میکرون در اسکله
B20: بدینوسیله امضا کنندگان ذیل تایید می نمایند , عملیات اعمال رنگ High Solid GLASS FLAKE EPOXY به وسیله دستگاه رنگ پاش بدون هوا (Airless) به ضخامت 250 میکرون در اسکله بر روی المان های ناحیه حد فاصل محور های 19 الی 45 ضلع جنوبی اسکله شرقی مطابق با ریزمتره پیوست به مساحت 184/4 متر مربع انجام گردید.
B26: ردیف | C26: ردیف فهرست بها | E26: شرح | I26: مقدار | K26: واحد
B28: 17 | C28: 641903107 | E28: اعمال رنگ High Solid GLASS FLAKE EPOXY به وسیله دستگاه رنگ پاش بدون هوا (Airless) به ضخامت 250 میکرون در اسکله | I28: 184/4 | K28: متر مربع
B31: پیمانکار | F31: دستگاه نظارت | J31: کار فرما
